<robot name="cyton_gamma_1500">
	
	<link name="link1">	
		<visual>
			<origin xyz="0 0 0.25" rpy="0 0 0" />
			<geometry>
				<box size="0.1 0.1 .5"/>
			</geometry>
		</visual>
	</link>
	<link name="link2">
		<visual>
			<origin xyz="0 0.1 0.25" rpy="0 0 0" />
			<geometry>
				<box size="0.05 0.05 .5"/>
			</geometry>
		</visual>
	</link>
	<link name="link3">
		<visual>
			<origin xyz="0 -0.03 0.25" rpy="0 0 0" />
			<geometry>
				<box size="0.025 0.025 .5"/>
			</geometry>
		</visual>
	</link>
	<link name="link4">
		<visual>
			<origin xyz="0 0.015 0.25" rpy="0 0 0" />
			<geometry>				
				<box size="0.0125 0.0125 .5"/>
			</geometry>
		</visual>
	</link>
	<link name="link5">
		<visual>
			<origin xyz="0 -0.01 0.25" rpy="0 0 0" />
			<geometry>				
				<box size="0.005 0.005 .5"/>
			</geometry>
		</visual>
	</link>
	<link name="link6">
		<visual>
			<origin xyz="0 0.01 0.25" rpy="0 0 0" />
			<geometry>				
				<box size="0.005 0.005 .5"/>
			</geometry>
		</visual>
	</link>





	<joint name="joint1" type="continuous">
      <parent link="link1"/>
      <child link="link2"/>
      <origin xyz="0 0 0.5" rpy="0 0 0" />
      <axis xyz="0.0 0.0 1.0" /> 
    </joint>

	<joint name="joint2" type="continuous">
		<parent link="link2"/>
		<child link="link3"/>
		<origin xyz="0 0 0.5" rpy="0 0 0" />
		<axis xyz="1.0 0.0 0.0" /> 
	</joint>

	<joint name="joint3" type="continuous">
		<parent link="link3"/>
		<child link="link4"/>
		<origin xyz="0 0 0.5" rpy="0 0 0" />
		<axis xyz="0.0 1.0 0.0" /> 
	</joint>

	<joint name="joint4" type="continuous">
		<parent link="link4"/>
		<child link="link5"/>
		<origin xyz="0 0 0.5" rpy="0 0 0" />
		<axis xyz="1.0 0.0 0.0" /> 
	</joint>

	<joint name="joint5" type="continuous">
		<parent link="link5"/>
		<child link="link6"/>
		<origin xyz="0 0 0.5" rpy="0 0 0" />
		<axis xyz="0.0 1.0 0.0" /> 
	</joint>



</robot>